{"uuid": "b661299e-3891-4a04-92c2-23623e2b814c", "children": ["a4039056-ea98-497d-9c26-5d6b2d55cb73", "2c867e63-610c-4181-80d2-e04c9f003522", "1e0fedc2-2bbf-4262-be00-274c32285979", "80897e00-a07a-4a02-8211-5af54382525b"], "befores": [{"name": "_xunit_setup_class_fixture_TestMain", "status": "broken", "statusDetails": {"message": "urllib3.exceptions.MaxRetryError: HTTPConnectionPool(host='127.0.0.1', port=4723): Max retries exceeded with url: /wd/hub/session (Caused by NewConnectionError('<urllib3.connection.HTTPConnection object at 0x000001C9701FE310>: Failed to establish a new connection: [WinError 10061] 由于目标计算机积极拒绝，无法连接。'))\n", "trace": "  File \"D:\\project\\venv\\lib\\site-packages\\pluggy\\_callers.py\", line 39, in _multicall\n    res = hook_impl.function(*args)\n  File \"D:\\project\\venv\\lib\\site-packages\\_pytest\\fixtures.py\", line 1129, in pytest_fixture_setup\n    result = call_fixture_func(fixturefunc, request, kwargs)\n  File \"D:\\project\\venv\\lib\\site-packages\\_pytest\\fixtures.py\", line 901, in call_fixture_func\n    fixture_result = next(generator)\n  File \"D:\\project\\venv\\lib\\site-packages\\_pytest\\python.py\", line 864, in xunit_setup_class_fixture\n    _call_with_optional_argument(func, self.obj)\n  File \"D:\\project\\venv\\lib\\site-packages\\_pytest\\python.py\", line 786, in _call_with_optional_argument\n    func(arg)\n  File \"D:\\project\\test_app\\test_wework_main.py\", line 30, in setup_class\n    self.driver = webdriver.Remote(\"http://127.0.0.1:4723/wd/hub\", caps)\n  File \"D:\\project\\venv\\lib\\site-packages\\appium\\webdriver\\webdriver.py\", line 230, in __init__\n    super().__init__(\n  File \"D:\\project\\venv\\lib\\site-packages\\selenium\\webdriver\\remote\\webdriver.py\", line 286, in __init__\n    self.start_session(capabilities, browser_profile)\n  File \"D:\\project\\venv\\lib\\site-packages\\appium\\webdriver\\webdriver.py\", line 320, in start_session\n    response = self.execute(RemoteCommand.NEW_SESSION, w3c_caps)\n  File \"D:\\project\\venv\\lib\\site-packages\\selenium\\webdriver\\remote\\webdriver.py\", line 438, in execute\n    response = self.command_executor.execute(driver_command, params)\n  File \"D:\\project\\venv\\lib\\site-packages\\selenium\\webdriver\\remote\\remote_connection.py\", line 290, in execute\n    return self._request(command_info[0], url, body=data)\n  File \"D:\\project\\venv\\lib\\site-packages\\selenium\\webdriver\\remote\\remote_connection.py\", line 311, in _request\n    response = self._conn.request(method, url, body=body, headers=headers)\n  File \"D:\\project\\venv\\lib\\site-packages\\urllib3\\request.py\", line 78, in request\n    return self.request_encode_body(\n  File \"D:\\project\\venv\\lib\\site-packages\\urllib3\\request.py\", line 170, in request_encode_body\n    return self.urlopen(method, url, **extra_kw)\n  File \"D:\\project\\venv\\lib\\site-packages\\urllib3\\poolmanager.py\", line 376, in urlopen\n    response = conn.urlopen(method, u.request_uri, **kw)\n  File \"D:\\project\\venv\\lib\\site-packages\\urllib3\\connectionpool.py\", line 815, in urlopen\n    return self.urlopen(\n  File \"D:\\project\\venv\\lib\\site-packages\\urllib3\\connectionpool.py\", line 815, in urlopen\n    return self.urlopen(\n  File \"D:\\project\\venv\\lib\\site-packages\\urllib3\\connectionpool.py\", line 815, in urlopen\n    return self.urlopen(\n  File \"D:\\project\\venv\\lib\\site-packages\\urllib3\\connectionpool.py\", line 787, in urlopen\n    retries = retries.increment(\n  File \"D:\\project\\venv\\lib\\site-packages\\urllib3\\util\\retry.py\", line 592, in increment\n    raise MaxRetryError(_pool, url, error or ResponseError(cause))\n"}, "start": 1680149002520, "stop": 1680149010542}], "start": 1680149002520, "stop": 1680149012009}